<?xml version="1.0" ?>
<!-- =================================================================================== -->
<!-- |    This document was autogenerated by xacro from src/igvc_description/urdf/robot.xacro | -->
<!-- |    EDITING THIS FILE BY HAND IS NOT RECOMMENDED                                 | -->
<!-- =================================================================================== -->
<robot name="igvc_bot">
  <link name="base_link">
    <visual>
      <geometry>
        <box size="0.5 0.4 0.2"/>
      </geometry>
      <origin xyz="0 0 0.15"/>
      <material name="body_color">
        <color rgba="0.15 0.15 0.18 1"/>
      </material>
    </visual>
    <collision>
      <geometry>
        <box size="0.5 0.4 0.2"/>
      </geometry>
      <origin xyz="0 0 0.15"/>
    </collision>
    <inertial>
      <mass value="10.0"/>
      <origin xyz="0 0 0.15"/>
      <inertia ixx="0.2" ixy="0" ixz="0" iyy="0.2" iyz="0" izz="0.2"/>
    </inertial>
  </link>
  <!-- Correct gazebo tag placement -->
  <gazebo reference="base_link">
    <self_collide>false</self_collide>
  </gazebo>
  <link name="wheel_fl_link">
    <visual>
      <origin rpy="1.5708 0 0"/>
      <geometry>
        <cylinder length="0.03" radius="0.05"/>
      </geometry>
      <material name="wheel_orange">
        <color rgba="1.0 0.4 0.0 1"/>
      </material>
    </visual>
    <collision>
      <origin rpy="1.5708 0 0"/>
      <geometry>
        <cylinder length="0.03" radius="0.05"/>
      </geometry>
    </collision>
    <inertial>
      <mass value="1.0"/>
      <origin xyz="0 0 0"/>
      <inertia ixx="0.01" ixy="0.0" ixz="0.0" iyy="0.01" iyz="0.0" izz="0.005"/>
    </inertial>
  </link>
  <joint name="wheel_fl_joint" type="continuous">
    <parent link="base_link"/>
    <child link="wheel_fl_link"/>
    <!-- Wheel center at wheel_radius -->
    <origin xyz="0.2 0.21 0.05"/>
    <axis xyz="0 1 0"/>
  </joint>
  <link name="wheel_fr_link">
    <visual>
      <origin rpy="1.5708 0 0"/>
      <geometry>
        <cylinder length="0.03" radius="0.05"/>
      </geometry>
      <material name="wheel_orange">
        <color rgba="1.0 0.4 0.0 1"/>
      </material>
    </visual>
    <collision>
      <origin rpy="1.5708 0 0"/>
      <geometry>
        <cylinder length="0.03" radius="0.05"/>
      </geometry>
    </collision>
    <inertial>
      <mass value="1.0"/>
      <origin xyz="0 0 0"/>
      <inertia ixx="0.01" ixy="0.0" ixz="0.0" iyy="0.01" iyz="0.0" izz="0.005"/>
    </inertial>
  </link>
  <joint name="wheel_fr_joint" type="continuous">
    <parent link="base_link"/>
    <child link="wheel_fr_link"/>
    <!-- Wheel center at wheel_radius -->
    <origin xyz="0.2 -0.21 0.05"/>
    <axis xyz="0 1 0"/>
  </joint>
  <link name="wheel_rl_link">
    <visual>
      <origin rpy="1.5708 0 0"/>
      <geometry>
        <cylinder length="0.03" radius="0.05"/>
      </geometry>
      <material name="wheel_orange">
        <color rgba="1.0 0.4 0.0 1"/>
      </material>
    </visual>
    <collision>
      <origin rpy="1.5708 0 0"/>
      <geometry>
        <cylinder length="0.03" radius="0.05"/>
      </geometry>
    </collision>
    <inertial>
      <mass value="1.0"/>
      <origin xyz="0 0 0"/>
      <inertia ixx="0.01" ixy="0.0" ixz="0.0" iyy="0.01" iyz="0.0" izz="0.005"/>
    </inertial>
  </link>
  <joint name="wheel_rl_joint" type="continuous">
    <parent link="base_link"/>
    <child link="wheel_rl_link"/>
    <!-- Wheel center at wheel_radius -->
    <origin xyz="-0.2 0.21 0.05"/>
    <axis xyz="0 1 0"/>
  </joint>
  <link name="wheel_rr_link">
    <visual>
      <origin rpy="1.5708 0 0"/>
      <geometry>
        <cylinder length="0.03" radius="0.05"/>
      </geometry>
      <material name="wheel_orange">
        <color rgba="1.0 0.4 0.0 1"/>
      </material>
    </visual>
    <collision>
      <origin rpy="1.5708 0 0"/>
      <geometry>
        <cylinder length="0.03" radius="0.05"/>
      </geometry>
    </collision>
    <inertial>
      <mass value="1.0"/>
      <origin xyz="0 0 0"/>
      <inertia ixx="0.01" ixy="0.0" ixz="0.0" iyy="0.01" iyz="0.0" izz="0.005"/>
    </inertial>
  </link>
  <joint name="wheel_rr_joint" type="continuous">
    <parent link="base_link"/>
    <child link="wheel_rr_link"/>
    <!-- Wheel center at wheel_radius -->
    <origin xyz="-0.2 -0.21 0.05"/>
    <axis xyz="0 1 0"/>
  </joint>
  <!-- ================= IMU ================= -->
  <link name="imu_link"/>
  <joint name="imu_joint" type="fixed">
    <parent link="base_link"/>
    <child link="imu_link"/>
    <origin xyz="0 0 0.30"/>
  </joint>
  <gazebo reference="imu_link">
    <sensor name="imu_sensor" type="imu">
      <always_on>true</always_on>
      <update_rate>100</update_rate>
      <topic>/imu</topic>
    </sensor>
  </gazebo>
  <!-- ================= LIDAR ================= -->
  <link name="lidar_link">
    <visual>
      <geometry>
        <cylinder length="0.05" radius="0.04"/>
      </geometry>
    </visual>
    <collision>
      <geometry>
        <cylinder length="0.05" radius="0.04"/>
      </geometry>
    </collision>
    <inertial>
      <mass value="0.1"/>
      <inertia ixx="0.0001" ixy="0" ixz="0" iyy="0.0001" iyz="0" izz="0.0001"/>
    </inertial>
  </link>
  <joint name="lidar_joint" type="fixed">
    <parent link="base_link"/>
    <child link="lidar_link"/>
    <origin xyz="0.15 0 0.55"/>
  </joint>
  <!-- ✅ Stable CPU Ray Lidar (No GPU Crash) -->
  <gazebo reference="lidar_link">
    <sensor name="lidar" type="ray">
      <always_on>true</always_on>
      <update_rate>30</update_rate>
      <visualize>true</visualize>
      <topic>scan</topic>
      <ray>
        <scan>
          <horizontal>
            <samples>360</samples>
            <min_angle>-3.14159</min_angle>
            <max_angle>3.14159</max_angle>
          </horizontal>
        </scan>
        <range>
          <min>0.1</min>
          <max>10.0</max>
        </range>
      </ray>
    </sensor>
  </gazebo>
  <!-- ================= CAMERA (visual only) ================= -->
  <link name="camera_link">
    <visual>
      <geometry>
        <box size="0.05 0.05 0.05"/>
      </geometry>
      <material name="sensor_green">
        <color rgba="0.0 1.0 0.3 1"/>
      </material>
    </visual>
  </link>
  <joint name="camera_joint" type="fixed">
    <parent link="base_link"/>
    <child link="camera_link"/>
    <origin xyz="0.22 0 0.27"/>
  </joint>
  <!-- IMU System -->
  <gazebo>
    <plugin filename="libgz-sim-imu-system.so" name="gz::sim::systems::Imu"/>
  </gazebo>
  <!-- Sensors System (handles lidar + camera) -->
  <gazebo>
    <plugin filename="libgz-sim-sensors-system.so" name="gz::sim::systems::Sensors"/>
  </gazebo>
  <!-- ================= GAZEBO DIFF DRIVE ================= -->
  <gazebo>
    <plugin filename="libgz-sim-diff-drive-system.so" name="gz::sim::systems::DiffDrive">
      <topic>/cmd_vel</topic>
      <odom_topic>/odom</odom_topic>
      <odom_frame>odom</odom_frame>
      <base_frame>base_link</base_frame>
      <!-- 🔥 ADD THESE -->
      <publish_tf>true</publish_tf>
      <publish_wheel_tf>true</publish_wheel_tf>
      <publish_joint_state>true</publish_joint_state>
      <left_joint>wheel_fl_joint</left_joint>
      <left_joint>wheel_rl_joint</left_joint>
      <right_joint>wheel_fr_joint</right_joint>
      <right_joint>wheel_rr_joint</right_joint>
      <wheel_separation>0.36</wheel_separation>
      <wheel_radius>0.05</wheel_radius>
      <update_rate>100</update_rate>
    </plugin>
  </gazebo>
</robot>
