<?xml version="1.0" ?>
<!-- =================================================================================== -->
<!-- |    This document was autogenerated by xacro from src/igvc_description/urdf/robot.xacro | -->
<!-- |    EDITING THIS FILE BY HAND IS NOT RECOMMENDED                                 | -->
<!-- =================================================================================== -->
<robot name="igvc_bot">
  <!-- Root link -->
  <link name="base_link"/>
  <!-- Chassis: the main body -->
  <link name="chassis_link">
    <visual>
      <origin xyz="0 0 0"/>
      <geometry>
        <!-- A simple box: length width height -->
        <box size="0.5 0.4 0.2"/>
      </geometry>
      <material name="grey">
        <color rgba="0.6 0.6 0.6 1"/>
      </material>
    </visual>
    <collision>
      <origin xyz="0 0 0"/>
      <geometry>
        <box size="0.5 0.4 0.2"/>
      </geometry>
    </collision>
    <inertial>
      <mass value="10.0"/>
      <origin xyz="0 0 0"/>
      <inertia ixx="0.2" ixy="0.0" ixz="0.0" iyy="0.2" iyz="0.0" izz="0.2"/>
    </inertial>
  </link>
  <!-- Fixed joint connecting base_link to chassis -->
  <joint name="base_to_chassis" type="fixed">
    <parent link="base_link"/>
    <child link="chassis_link"/>
    <origin xyz="0 0 0"/>
  </joint>
  <link name="wheel_fl_link">
    <visual>
      <origin rpy="1.5708 0 0" xyz="0 0 0"/>
      <geometry>
        <cylinder length="0.03" radius="0.05"/>
      </geometry>
      <material name="black">
        <color rgba="0.1 0.1 0.1 1"/>
      </material>
    </visual>
    <collision>
      <origin rpy="1.5708 0 0" xyz="0 0 0"/>
      <geometry>
        <cylinder length="0.03" radius="0.05"/>
      </geometry>
    </collision>
    <inertial>
      <mass value="1.0"/>
      <origin xyz="0 0 0"/>
      <inertia ixx="0.01" iyy="0.01" izz="0.01"/>
    </inertial>
  </link>
  <joint name="wheel_fl_joint" type="continuous">
    <parent link="chassis_link"/>
    <child link="wheel_fl_link"/>
    <origin xyz="0.2 0.18 -0.1"/>
    <axis xyz="0 1 0"/>
  </joint>
  <link name="wheel_fr_link">
    <visual>
      <origin rpy="1.5708 0 0" xyz="0 0 0"/>
      <geometry>
        <cylinder length="0.03" radius="0.05"/>
      </geometry>
      <material name="black">
        <color rgba="0.1 0.1 0.1 1"/>
      </material>
    </visual>
    <collision>
      <origin rpy="1.5708 0 0" xyz="0 0 0"/>
      <geometry>
        <cylinder length="0.03" radius="0.05"/>
      </geometry>
    </collision>
    <inertial>
      <mass value="1.0"/>
      <origin xyz="0 0 0"/>
      <inertia ixx="0.01" iyy="0.01" izz="0.01"/>
    </inertial>
  </link>
  <joint name="wheel_fr_joint" type="continuous">
    <parent link="chassis_link"/>
    <child link="wheel_fr_link"/>
    <origin xyz="0.2 -0.18 -0.1"/>
    <axis xyz="0 1 0"/>
  </joint>
  <link name="wheel_rl_link">
    <visual>
      <origin rpy="1.5708 0 0" xyz="0 0 0"/>
      <geometry>
        <cylinder length="0.03" radius="0.05"/>
      </geometry>
      <material name="black">
        <color rgba="0.1 0.1 0.1 1"/>
      </material>
    </visual>
    <collision>
      <origin rpy="1.5708 0 0" xyz="0 0 0"/>
      <geometry>
        <cylinder length="0.03" radius="0.05"/>
      </geometry>
    </collision>
    <inertial>
      <mass value="1.0"/>
      <origin xyz="0 0 0"/>
      <inertia ixx="0.01" iyy="0.01" izz="0.01"/>
    </inertial>
  </link>
  <joint name="wheel_rl_joint" type="continuous">
    <parent link="chassis_link"/>
    <child link="wheel_rl_link"/>
    <origin xyz="-0.2 0.18 -0.1"/>
    <axis xyz="0 1 0"/>
  </joint>
  <link name="wheel_rr_link">
    <visual>
      <origin rpy="1.5708 0 0" xyz="0 0 0"/>
      <geometry>
        <cylinder length="0.03" radius="0.05"/>
      </geometry>
      <material name="black">
        <color rgba="0.1 0.1 0.1 1"/>
      </material>
    </visual>
    <collision>
      <origin rpy="1.5708 0 0" xyz="0 0 0"/>
      <geometry>
        <cylinder length="0.03" radius="0.05"/>
      </geometry>
    </collision>
    <inertial>
      <mass value="1.0"/>
      <origin xyz="0 0 0"/>
      <inertia ixx="0.01" iyy="0.01" izz="0.01"/>
    </inertial>
  </link>
  <joint name="wheel_rr_joint" type="continuous">
    <parent link="chassis_link"/>
    <child link="wheel_rr_link"/>
    <origin xyz="-0.2 -0.18 -0.1"/>
    <axis xyz="0 1 0"/>
  </joint>
  <!-- ================= IMU ================= -->
  <link name="imu_link"/>
  <joint name="imu_joint" type="fixed">
    <parent link="chassis_link"/>
    <child link="imu_link"/>
    <!-- IMU placed on top of chassis -->
    <origin xyz="0 0 0.12"/>
  </joint>
  <!-- ================= 2D LiDAR ================= -->
  <link name="lidar_link"/>
  <joint name="lidar_joint" type="fixed">
    <parent link="chassis_link"/>
    <child link="lidar_link"/>
    <!-- LiDAR at front-top -->
    <origin xyz="0.25 0 0.15"/>
  </joint>
  <!-- ================= RGB-D Camera ================= -->
  <link name="camera_link"/>
  <joint name="camera_joint" type="fixed">
    <parent link="chassis_link"/>
    <child link="camera_link"/>
    <!-- Camera at front -->
    <origin xyz="0.30 0 0.12"/>
  </joint>
  <!-- ================= IMU PLUGIN ================= -->
  <gazebo>
    <plugin filename="gz-sim-imu-system" name="imu_plugin">
      <topic>/imu/data</topic>
      <frame_id>imu_link</frame_id>
    </plugin>
  </gazebo>
  <!-- ================= 2D LIDAR PLUGIN ================= -->
  <gazebo>
    <plugin filename="gz-sim-lidar-system" name="lidar_plugin">
      <topic>/scan</topic>
      <frame_id>lidar_link</frame_id>
      <update_rate>10</update_rate>
      <horizontal>
        <samples>720</samples>
        <resolution>1</resolution>
        <min_angle>-3.14159</min_angle>
        <max_angle>3.14159</max_angle>
      </horizontal>
      <range>
        <min>0.12</min>
        <max>10.0</max>
      </range>
    </plugin>
  </gazebo>
  <!-- ================= RGB-D CAMERA PLUGIN ================= -->
  <gazebo>
    <plugin filename="gz-sim-depth-camera-system" name="camera_plugin">
      <camera_name>front_camera</camera_name>
      <frame_id>camera_link</frame_id>
      <image_topic>/camera/image_raw</image_topic>
      <depth_image_topic>/camera/depth/image_raw</depth_image_topic>
      <update_rate>30</update_rate>
      <horizontal_fov>1.047</horizontal_fov>
      <image>
        <width>640</width>
        <height>480</height>
        <format>R8G8B8</format>
      </image>
    </plugin>
  </gazebo>
</robot>
